Workbook

Sheet Tableau de Bord
A1: CENTRE AQUATIQUE – TABLEAU DE BORD ANNUEL 2025
A2: Données fictives – Janvier à Décembre 2025
A4: FRÉQUENTATION
A5: Indicateur | B5: Janvier | C5: Février | D5: Mars | E5: Avril | F5: Mai | G5: Juin | H5: Juillet | I5: Août | J5: Septembre | K5: Octobre | L5: Novembre | M5: Décembre | N5: Total 2025 | O5: Évol. Jan→Déc
A6: Entrées totales | B6: =Fréquentation!G9 -> 8024 | C6: =Fréquentation!G17 -> 8238 | D6: =Fréquentation!G25 -> 8134 | E6: =Fréquentation!G33 -> 8074 | F6: =Fréquentation!G41 -> 7720 | G6: =Fréquentation!G49 -> 8141 | H6: =Fréquentation!G57 -> 6845 | I6: =Fréquentation!G65 -> 5464 | J6: =Fréquentation!G73 -> 6237 | K6: =Fréquentation!G81 -> 6118 | L6: =Fréquentation!G89 -> 5739 | M6: =Fréquentation!G97 -> 4990 | N6: =SUM(B6:M6) -> 83724 | O6: =IF(B6<>0,(M6-B6)/B6,0) -> -0.37811565
A7: dont Adultes | B7: =Fréquentation!B9 -> 3393 | C7: =Fréquentation!B17 -> 3292 | D7: =Fréquentation!B25 -> 3379 | E7: =Fréquentation!B33 -> 3225 | F7: =Fréquentation!B41 -> 3098 | G7: =Fréquentation!B49 -> 3317 | H7: =Fréquentation!B57 -> 2730 | I7: =Fréquentation!B65 -> 2248 | J7: =Fréquentation!B73 -> 2718 | K7: =Fréquentation!B81 -> 2589 | L7: =Fréquentation!B89 -> 2408 | M7: =Fréquentation!B97 -> 2016 | N7: =SUM(B7:M7) -> 34413 | O7: =IF(B7<>0,(M7-B7)/B7,0) -> -0.40583554
A8: dont Enfants | B8: =Fréquentation!C9 -> 1403 | C8: =Fréquentation!C17 -> 1675 | D8: =Fréquentation!C25 -> 1369 | E8: =Fréquentation!C33 -> 1612 | F8: =Fréquentation!C41 -> 1341 | G8: =Fréquentation!C49 -> 1429 | H8: =Fréquentation!C57 -> 1681 | I8: =Fréquentation!C65 -> 1353 | J8: =Fréquentation!C73 -> 843 | K8: =Fréquentation!C81 -> 960 | L8: =Fréquentation!C89 -> 774 | M8: =Fréquentation!C97 -> 851 | N8: =SUM(B8:M8) -> 15291 | O8: =IF(B8<>0,(M8-B8)/B8,0) -> -0.39344262
A9: dont Scolaires | B9: =Fréquentation!D9 -> 777 | C9: =Fréquentation!D17 -> 689 | D9: =Fréquentation!D25 -> 803 | E9: =Fréquentation!D33 -> 637 | F9: =Fréquentation!D41 -> 728 | G9: =Fréquentation!D49 -> 779 | H9: =Fréquentation!D57 -> 172 | I9: =Fréquentation!D65 -> 0 | J9: =Fréquentation!D73 -> 674 | K9: =Fréquentation!D81 -> 642 | L9: =Fréquentation!D89 -> 793 | M9: =Fréquentation!D97 -> 574 | N9: =SUM(B9:M9) -> 7268 | O9: =IF(B9<>0,(M9-B9)/B9,0) -> -0.26126126
A10: dont Abonnés (passages) | B10: =Fréquentation!E9 -> 1979 | C10: =Fréquentation!E17 -> 2030 | D10: =Fréquentation!E25 -> 2054 | E10: =Fréquentation!E33 -> 2045 | F10: =Fréquentation!E41 -> 1994 | G10: =Fréquentation!E49 -> 2019 | H10: =Fréquentation!E57 -> 1656 | I10: =Fréquentation!E65 -> 1358 | J10: =Fréquentation!E73 -> 1664 | K10: =Fréquentation!E81 -> 1570 | L10: =Fréquentation!E89 -> 1457 | M10: =Fréquentation!E97 -> 1218 | N10: =SUM(B10:M10) -> 21044 | O10: =IF(B10<>0,(M10-B10)/B10,0) -> -0.38453765
A11: dont Occasionnels | B11: =Fréquentation!F9 -> 472 | C11: =Fréquentation!F17 -> 552 | D11: =Fréquentation!F25 -> 529 | E11: =Fréquentation!F33 -> 555 | F11: =Fréquentation!F41 -> 559 | G11: =Fréquentation!F49 -> 597 | H11: =Fréquentation!F57 -> 606 | I11: =Fréquentation!F65 -> 505 | J11: =Fréquentation!F73 -> 338 | K11: =Fréquentation!F81 -> 357 | L11: =Fréquentation!F89 -> 307 | M11: =Fréquentation!F97 -> 331 | N11: =SUM(B11:M11) -> 5708 | O11: =IF(B11<>0,(M11-B11)/B11,0) -> -0.29872881
A12: Abonnés actifs (moy) | B12: 548 | C12: 552 | D12: 559 | E12: 563 | F12: 566 | G12: 570 | H12: 561 | I12: 540 | J12: 512 | K12: 489 | L12: 461 | M12: 437 | N12: =AVERAGE(B12:M12) -> 529.83333 | O12: =IF(B12<>0,(M12-B12)/B12,0) -> -0.20255474
A13: Taux d'occupation (moy) | B13: =Fréquentation!H9 -> 0.7435 | C13: =Fréquentation!H17 -> 0.75825 | D13: =Fréquentation!H25 -> 0.75175 | E13: =Fréquentation!H33 -> 0.74975 | F13: =Fréquentation!H41 -> 0.7135 | G13: =Fréquentation!H49 -> 0.75325 | H13: =Fréquentation!H57 -> 0.634 | I13: =Fréquentation!H65 -> 0.505 | J13: =Fréquentation!H73 -> 0.577 | K13: =Fréquentation!H81 -> 0.56675 | L13: =Fréquentation!H89 -> 0.533 | M13: =Fréquentation!H97 -> 0.464 | N13: =AVERAGE(B13:M13) -> 0.6458125 | O13: =IF(B13<>0,(M13-B13)/B13,0) -> -0.37592468
A14: Entrées totales N-1 (2024) | B14: 8030 | C14: 7850 | D14: 7890 | E14: 8060 | F14: 7530 | G14: 8080 | H14: 7510 | I14: 6800 | J14: 7640 | K14: 8010 | L14: 7630 | M14: 7280 | N14: =SUM(B14:M14) -> 92310 | O14: =IF(B14<>0,(M14-B14)/B14,0) -> -0.093399751
A15: Écart entrées vs N-1 | B15: =IF(B14<>0,(B6-B14)/B14,0) -> -0.00074719801 | C15: =IF(C14<>0,(C6-C14)/C14,0) -> 0.049426752 | D15: =IF(D14<>0,(D6-D14)/D14,0) -> 0.030925222 | E15: =IF(E14<>0,(E6-E14)/E14,0) -> 0.0017369727 | F15: =IF(F14<>0,(F6-F14)/F14,0) -> 0.025232404 | G15: =IF(G14<>0,(G6-G14)/G14,0) -> 0.007549505 | H15: =IF(H14<>0,(H6-H14)/H14,0) -> -0.088548602 | I15: =IF(I14<>0,(I6-I14)/I14,0) -> -0.19647059 | ... N15: =IF(N14<>0,(N6-N14)/N14,0) -> -0.093012675 | O15: –
A16: Réclamations usagers (nb) | B16: 3 | C16: 2 | D16: 4 | E16: 3 | F16: 2 | G16: 3 | H16: 14 | I16: 19 | J16: 26 | K16: 23 | L16: 27 | M16: 22 | N16: =SUM(B16:M16) -> 148 | O16: =IF(B16<>0,(M16-B16)/B16,0) -> 6.3333333
A18: FINANCES (€)
A19: Indicateur | B19: Janvier | C19: Février | D19: Mars | E19: Avril | F19: Mai | G19: Juin | H19: Juillet | I19: Août | J19: Septembre | K19: Octobre | L19: Novembre | M19: Décembre | N19: Total 2025 | O19: Évol. Jan→Déc
A20: Recettes Billetterie | B20: =Finances!C5 -> 31610 | C20: =Finances!D5 -> 32300 | D20: =Finances!E5 -> 31730 | E20: =Finances!F5 -> 31490 | F20: =Finances!G5 -> 29810 | G20: =Finances!H5 -> 31880 | H20: =Finances!I5 -> 27670 | I20: =Finances!J5 -> 22280 | ... M20: =Finances!N5 -> 19420 | N20: =SUM(B20:M20) -> 328010 | O20: =IF(B20<>0,(M20-B20)/B20,0) -> -0.38563746
A21: Recettes Abonnements | B21: =Finances!C6 -> 26852 | C21: =Finances!D6 -> 27048 | D21: =Finances!E6 -> 27391 | E21: =Finances!F6 -> 27587 | F21: =Finances!G6 -> 27734 | G21: =Finances!H6 -> 27930 | H21: =Finances!I6 -> 27489 | I21: =Finances!J6 -> 26460 | ... M21: =Finances!N6 -> 21413 | N21: =SUM(B21:M21) -> 311542 | O21: =IF(B21<>0,(M21-B21)/B21,0) -> -0.20255474
A22: Recettes Cours | B22: =Finances!C7 -> 10450 | C22: =Finances!D7 -> 10610 | D22: =Finances!E7 -> 10740 | E22: =Finances!F7 -> 10160 | F22: =Finances!G7 -> 10330 | G22: =Finances!H7 -> 9450 | H22: =Finances!I7 -> 4360 | I22: =Finances!J7 -> 2670 | ... M22: =Finances!N7 -> 4340 | N22: =SUM(B22:M22) -> 91490 | O22: =IF(B22<>0,(M22-B22)/B22,0) -> -0.584689
A23: Recettes Location | B23: =Finances!C8 -> 1770 | C23: =Finances!D8 -> 1810 | D23: =Finances!E8 -> 1790 | E23: =Finances!F8 -> 1780 | F23: =Finances!G8 -> 1700 | G23: =Finances!H8 -> 1790 | H23: =Finances!I8 -> 1510 | I23: =Finances!J8 -> 1200 | ... M23: =Finances!N8 -> 1100 | N23: =SUM(B23:M23) -> 18430 | O23: =IF(B23<>0,(M23-B23)/B23,0) -> -0.37853107
A24: Recettes Restauration | B24: =Finances!C9 -> 3050 | C24: =Finances!D9 -> 3130 | D24: =Finances!E9 -> 3090 | E24: =Finances!F9 -> 3070 | F24: =Finances!G9 -> 2930 | G24: =Finances!H9 -> 3090 | H24: =Finances!I9 -> 2600 | I24: =Finances!J9 -> 2080 | ... M24: =Finances!N9 -> 1900 | N24: =SUM(B24:M24) -> 31810 | O24: =IF(B24<>0,(M24-B24)/B24,0) -> -0.37704918
A25: Recettes Autres | B25: =Finances!C10 -> 1000 | C25: =Finances!D10 -> 1100 | D25: =Finances!E10 -> 1300 | E25: =Finances!F10 -> 1140 | F25: =Finances!G10 -> 1340 | G25: =Finances!H10 -> 1340 | H25: =Finances!I10 -> 1110 | I25: =Finances!J10 -> 1000 | ... M25: =Finances!N10 -> 1020 | N25: =SUM(B25:M25) -> 13930 | O25: =IF(B25<>0,(M25-B25)/B25,0) -> 0.02
A26: TOTAL RECETTES | B26: =SUM(B20:B25) -> 74732 | C26: =SUM(C20:C25) -> 75998 | D26: =SUM(D20:D25) -> 76041 | E26: =SUM(E20:E25) -> 75227 | F26: =SUM(F20:F25) -> 73844 | G26: =SUM(G20:G25) -> 75480 | H26: =SUM(H20:H25) -> 64739 | I26: =SUM(I20:I25) -> 55690 | ... M26: =SUM(M20:M25) -> 49193 | N26: =SUM(B26:M26) -> 795212 | O26: =IF(B26<>0,(M26-B26)/B26,0) -> -0.34174116
A27: Charges Personnel | B27: =Finances!C15 -> 36800 | C27: =Finances!D15 -> 36800 | D27: =Finances!E15 -> 36800 | E27: =Finances!F15 -> 36800 | F27: =Finances!G15 -> 36800 | G27: =Finances!H15 -> 36800 | H27: =Finances!I15 -> 39800 | I27: =Finances!J15 -> 39800 | ... M27: =Finances!N15 -> 36800 | N27: =SUM(B27:M27) -> 447600 | O27: =IF(B27<>0,(M27-B27)/B27,0) -> 0
A28: Charges Patronales | B28: =Finances!C16 -> 18400 | C28: =Finances!D16 -> 18400 | D28: =Finances!E16 -> 18400 | E28: =Finances!F16 -> 18400 | F28: =Finances!G16 -> 18400 | G28: =Finances!H16 -> 18400 | H28: =Finances!I16 -> 19900 | I28: =Finances!J16 -> 19900 | ... M28: =Finances!N16 -> 18400 | N28: =SUM(B28:M28) -> 223800 | O28: =IF(B28<>0,(M28-B28)/B28,0) -> 0
A29: Charges Électricité | B29: =Finances!C17 -> 5484 | C29: =Finances!D17 -> 5515 | D29: =Finances!E17 -> 5534 | E29: =Finances!F17 -> 6087 | F29: =Finances!G17 -> 6654 | G29: =Finances!H17 -> 7304 | H29: =Finances!I17 -> 7396 | I29: =Finances!J17 -> 7344 | ... M29: =Finances!N17 -> 8392 | N29: =SUM(B29:M29) -> 83355 | O29: =IF(B29<>0,(M29-B29)/B29,0) -> 0.53026988
A30: Charges Gaz | B30: =Finances!C18 -> 4377 | C30: =Finances!D18 -> 4461 | D30: =Finances!E18 -> 4214 | E30: =Finances!F18 -> 4462 | F30: =Finances!G18 -> 4793 | G30: =Finances!H18 -> 5160 | H30: =Finances!I18 -> 4414 | I30: =Finances!J18 -> 4254 | ... M30: =Finances!N18 -> 6817 | N30: =SUM(B30:M30) -> 59373 | O30: =IF(B30<>0,(M30-B30)/B30,0) -> 0.55745945
A31: Charges Eau | B31: =Finances!C19 -> 3368 | C31: =Finances!D19 -> 3422 | D31: =Finances!E19 -> 3394 | E31: =Finances!F19 -> 3378 | F31: =Finances!G19 -> 3288 | G31: =Finances!H19 -> 3396 | H31: =Finances!I19 -> 3058 | I31: =Finances!J19 -> 2702 | ... M31: =Finances!N19 -> 2574 | N31: =SUM(B31:M31) -> 37124 | O31: =IF(B31<>0,(M31-B31)/B31,0) -> -0.23574822
A32: Charges Produits Chim. | B32: =Finances!C20 -> 3040 | C32: =Finances!D20 -> 3060 | D32: =Finances!E20 -> 3050 | E32: =Finances!F20 -> 3050 | F32: =Finances!G20 -> 3020 | G32: =Finances!H20 -> 3050 | H32: =Finances!I20 -> 2950 | I32: =Finances!J20 -> 2840 | ... M32: =Finances!N20 -> 2800 | N32: =SUM(B32:M32) -> 35510 | O32: =IF(B32<>0,(M32-B32)/B32,0) -> -0.078947368
A33: Charges Maint. Préventive | B33: =Finances!C21 -> 2500 | C33: =Finances!D21 -> 2500 | D33: =Finances!E21 -> 2500 | E33: =Finances!F21 -> 2500 | F33: =Finances!G21 -> 2500 | G33: =Finances!H21 -> 2500 | H33: =Finances!I21 -> 2500 | I33: =Finances!J21 -> 2500 | ... M33: =Finances!N21 -> 2500 | N33: =SUM(B33:M33) -> 30000 | O33: =IF(B33<>0,(M33-B33)/B33,0) -> 0
A34: Charges Maint. Corrective | B34: =Finances!C22 -> 850 | C34: =Finances!D22 -> 1420 | D34: =Finances!E22 -> 610 | E34: =Finances!F22 -> 980 | F34: =Finances!G22 -> 1250 | G34: =Finances!H22 -> 720 | H34: =Finances!I22 -> 1980 | I34: =Finances!J22 -> 540 | ... M34: =Finances!N22 -> 940 | N34: =SUM(B34:M34) -> 12840 | O34: =IF(B34<>0,(M34-B34)/B34,0) -> 0.10588235
A35: Charges Assurances | B35: =Finances!C23 -> 1500 | C35: =Finances!D23 -> 1500 | D35: =Finances!E23 -> 1500 | E35: =Finances!F23 -> 1500 | F35: =Finances!G23 -> 1500 | G35: =Finances!H23 -> 1500 | H35: =Finances!I23 -> 1500 | I35: =Finances!J23 -> 1500 | ... M35: =Finances!N23 -> 1500 | N35: =SUM(B35:M35) -> 18000 | O35: =IF(B35<>0,(M35-B35)/B35,0) -> 0
A36: Charges Autres | B36: =Finances!C24 -> 1170 | C36: =Finances!D24 -> 1080 | D36: =Finances!E24 -> 1000 | E36: =Finances!F24 -> 1000 | F36: =Finances!G24 -> 1020 | G36: =Finances!H24 -> 1040 | H36: =Finances!I24 -> 1110 | I36: =Finances!J24 -> 1050 | ... M36: =Finances!N24 -> 1160 | N36: =SUM(B36:M36) -> 12840 | O36: =IF(B36<>0,(M36-B36)/B36,0) -> -0.0085470085
A37: TOTAL CHARGES | B37: =SUM(B27:B36) -> 77489 | C37: =SUM(C27:C36) -> 78158 | D37: =SUM(D27:D36) -> 77002 | E37: =SUM(E27:E36) -> 78157 | F37: =SUM(F27:F36) -> 79225 | G37: =SUM(G27:G36) -> 79870 | H37: =SUM(H27:H36) -> 84608 | I37: =SUM(I27:I36) -> 82430 | ... M37: =SUM(M27:M36) -> 81883 | N37: =SUM(B37:M37) -> 960442 | O37: =IF(B37<>0,(M37-B37)/B37,0) -> 0.056704823
A38: RÉSULTAT D'EXPLOITATION | B38: =B26-B37 -> -2757 | C38: =C26-C37 -> -2160 | D38: =D26-D37 -> -961 | E38: =E26-E37 -> -2930 | F38: =F26-F37 -> -5381 | G38: =G26-G37 -> -4390 | H38: =H26-H37 -> -19869 | I38: =I26-I37 -> -26740 | ... N38: =N26-N37 -> -165230 | O38: =IF(B38<>0,(M38-B38)/B38,0) -> 10.857091
A40: QUALITÉ DE L'EAU & HYGIÈNE (moyennes mensuelles)
A41: Indicateur | B41: Janvier | C41: Février | D41: Mars | E41: Avril | F41: Mai | G41: Juin | H41: Juillet | I41: Août | J41: Septembre | K41: Octobre | L41: Novembre | M41: Décembre | N41: Total 2025 | O41: Évol. Jan→Déc
A42: pH (cible 7.2–7.6) | B42: =AVERAGE('Qualité Eau'!B13:B16) -> 7.325 | C42: =AVERAGE('Qualité Eau'!B17:B20) -> 7.4 | D42: =AVERAGE('Qualité Eau'!B21:B24) -> 7.45 | E42: =AVERAGE('Qualité Eau'!B25:B28) -> 7.45 | F42: =AVERAGE('Qualité Eau'!B29:B32) -> 7.35 | G42: =AVERAGE('Qualité Eau'!B33:B36) -> 7.425 | H42: =AVERAGE('Qualité Eau'!B37:B40) -> 7.4 | I42: =AVERAGE('Qualité Eau'!B41:B44) -> 7.375 | J42: =AVERAGE('Qualité Eau'!B45:B48) -> 7.375 | K42: =AVERAGE('Qualité Eau'!B49:B52) -> 7.375 | L42: =AVERAGE('Qualité Eau'!B53:B56) -> 7.45 | M42: =AVERAGE('Qualité Eau'!B57:B60) -> 7.45 | N42: =AVERAGE(B42:M42) -> 7.4020833 | O42: –
A43: Chlore libre mg/L | B43: =AVERAGE('Qualité Eau'!C13:C16) -> 1.025 | C43: =AVERAGE('Qualité Eau'!C17:C20) -> 1.225 | D43: =AVERAGE('Qualité Eau'!C21:C24) -> 1.225 | E43: =AVERAGE('Qualité Eau'!C25:C28) -> 1.225 | F43: =AVERAGE('Qualité Eau'!C29:C32) -> 1.1 | G43: =AVERAGE('Qualité Eau'!C33:C36) -> 1.1 | H43: =AVERAGE('Qualité Eau'!C37:C40) -> 1.1 | I43: =AVERAGE('Qualité Eau'!C41:C44) -> 1 | J43: =AVERAGE('Qualité Eau'!C45:C48) -> 1.2 | K43: =AVERAGE('Qualité Eau'!C49:C52) -> 1.1 | L43: =AVERAGE('Qualité Eau'!C53:C56) -> 1.2 | M43: =AVERAGE('Qualité Eau'!C57:C60) -> 1.175 | N43: =AVERAGE(B43:M43) -> 1.1395833 | O43: –
...

Sheet Fréquentation
A1: FRÉQUENTATION DÉTAILLÉE – JANVIER À DÉCEMBRE 2025 (48 semaines)
A3: JANVIER 2025
A4: Semaine | B4: Adultes | C4: Enfants | D4: Scolaires | E4: Abonnés | F4: Occasionnels | G4: Total Entrées | H4: Taux Occ.
A5: Janv. S1 (06-12 jan) | B5: 840 | C5: 348 | D5: 200 | E5: 494 | F5: 115 | G5: =SUM(B5:F5) -> 1997 | H5: 0.74
A6: Janv. S2 (13-19 jan) | B6: 868 | C6: 345 | D6: 191 | E6: 501 | F6: 116 | G6: =SUM(B6:F6) -> 2021 | H6: 0.753
A7: Janv. S3 (20-26 jan) | B7: 848 | C7: 357 | D7: 192 | E7: 489 | F7: 114 | G7: =SUM(B7:F7) -> 2000 | H7: 0.738
A8: Janv. S4 (27-31 jan) | B8: 837 | C8: 353 | D8: 194 | E8: 495 | F8: 127 | G8: =SUM(B8:F8) -> 2006 | H8: 0.743
A9: TOTAL JANVIER | B9: =SUM(B5:B8) -> 3393 | C9: =SUM(C5:C8) -> 1403 | D9: =SUM(D5:D8) -> 777 | E9: =SUM(E5:E8) -> 1979 | F9: =SUM(F5:F8) -> 472 | G9: =SUM(G5:G8) -> 8024 | H9: =AVERAGE(H5:H8) -> 0.7435
A11: FÉVRIER 2025
A12: Semaine | B12: Adultes | C12: Enfants | D12: Scolaires | E12: Abonnés | F12: Occasionnels | G12: Total Entrées | H12: Taux Occ.
A13: Fév. S1 (03-09 fév) | B13: 852 | C13: 436 | D13: 172 | E13: 521 | F13: 134 | G13: =SUM(B13:F13) -> 2115 | H13: 0.782
A14: Fév. S2 (10-16 fév) | B14: 834 | C14: 408 | D14: 171 | E14: 495 | F14: 129 | G14: =SUM(B14:F14) -> 2037 | H14: 0.748
A15: Fév. S3 (17-23 fév) | B15: 789 | C15: 428 | D15: 171 | E15: 504 | F15: 146 | G15: =SUM(B15:F15) -> 2038 | H15: 0.752
A16: Fév. S4 (24-28 fév) | B16: 817 | C16: 403 | D16: 175 | E16: 510 | F16: 143 | G16: =SUM(B16:F16) -> 2048 | H16: 0.751
A17: TOTAL FÉVRIER | B17: =SUM(B13:B16) -> 3292 | C17: =SUM(C13:C16) -> 1675 | D17: =SUM(D13:D16) -> 689 | E17: =SUM(E13:E16) -> 2030 | F17: =SUM(F13:F16) -> 552 | G17: =SUM(G13:G16) -> 8238 | H17: =AVERAGE(H13:H16) -> 0.75825
A19: MARS 2025
A20: Semaine | B20: Adultes | C20: Enfants | D20: Scolaires | E20: Abonnés | F20: Occasionnels | G20: Total Entrées | H20: Taux Occ.
A21: Mars S1 (03-09 mar) | B21: 833 | C21: 340 | D21: 206 | E21: 513 | F21: 133 | G21: =SUM(B21:F21) -> 2025 | H21: 0.748
A22: Mars S2 (10-16 mar) | B22: 862 | C22: 345 | D22: 203 | E22: 517 | F22: 135 | G22: =SUM(B22:F22) -> 2062 | H22: 0.758
A23: Mars S3 (17-23 mar) | B23: 862 | C23: 351 | D23: 197 | E23: 514 | F23: 130 | G23: =SUM(B23:F23) -> 2054 | H23: 0.758
A24: Mars S4 (24-31 mar) | B24: 822 | C24: 333 | D24: 197 | E24: 510 | F24: 131 | G24: =SUM(B24:F24) -> 1993 | H24: 0.743
A25: TOTAL MARS | B25: =SUM(B21:B24) -> 3379 | C25: =SUM(C21:C24) -> 1369 | D25: =SUM(D21:D24) -> 803 | E25: =SUM(E21:E24) -> 2054 | F25: =SUM(F21:F24) -> 529 | G25: =SUM(G21:G24) -> 8134 | H25: =AVERAGE(H21:H24) -> 0.75175
A27: AVRIL 2025
A28: Semaine | B28: Adultes | C28: Enfants | D28: Scolaires | E28: Abonnés | F28: Occasionnels | G28: Total Entrées | H28: Taux Occ.
A29: Avr. S1 (07-13 avr) | B29: 814 | C29: 392 | D29: 156 | E29: 512 | F29: 136 | G29: =SUM(B29:F29) -> 2010 | H29: 0.737
A30: Avr. S2 (14-20 avr) | B30: 794 | C30: 414 | D30: 162 | E30: 517 | F30: 144 | G30: =SUM(B30:F30) -> 2031 | H30: 0.759
A31: Avr. S3 (21-27 avr) | B31: 808 | C31: 403 | D31: 158 | E31: 503 | F31: 138 | G31: =SUM(B31:F31) -> 2010 | H31: 0.751
A32: Avr. S4 (28-30 avr) | B32: 809 | C32: 403 | D32: 161 | E32: 513 | F32: 137 | G32: =SUM(B32:F32) -> 2023 | H32: 0.752
A33: TOTAL AVRIL | B33: =SUM(B29:B32) -> 3225 | C33: =SUM(C29:C32) -> 1612 | D33: =SUM(D29:D32) -> 637 | E33: =SUM(E29:E32) -> 2045 | F33: =SUM(F29:F32) -> 555 | G33: =SUM(G29:G32) -> 8074 | H33: =AVERAGE(H29:H32) -> 0.74975
A35: MAI 2025
A36: Semaine | B36: Adultes | C36: Enfants | D36: Scolaires | E36: Abonnés | F36: Occasionnels | G36: Total Entrées | H36: Taux Occ.
A37: Mai S1 (05-11 mai) | B37: 771 | C37: 323 | D37: 179 | E37: 505 | F37: 140 | G37: =SUM(B37:F37) -> 1918 | H37: 0.705
A38: Mai S2 (12-18 mai) | B38: 780 | C38: 322 | D38: 181 | E38: 496 | F38: 130 | G38: =SUM(B38:F38) -> 1909 | H38: 0.702
A39: Mai S3 (19-25 mai) | B39: 775 | C39: 349 | D39: 184 | E39: 498 | F39: 144 | G39: =SUM(B39:F39) -> 1950 | H39: 0.726
A40: Mai S4 (26-31 mai) | B40: 772 | C40: 347 | D40: 184 | E40: 495 | F40: 145 | G40: =SUM(B40:F40) -> 1943 | H40: 0.721
A41: TOTAL MAI | B41: =SUM(B37:B40) -> 3098 | C41: =SUM(C37:C40) -> 1341 | D41: =SUM(D37:D40) -> 728 | E41: =SUM(E37:E40) -> 1994 | F41: =SUM(F37:F40) -> 559 | G41: =SUM(G37:G40) -> 7720 | H41: =AVERAGE(H37:H40) -> 0.7135
A43: JUIN 2025
A44: Semaine | B44: Adultes | C44: Enfants | D44: Scolaires | E44: Abonnés | F44: Occasionnels | G44: Total Entrées | H44: Taux Occ.
A45: Juin S1 (02-08 jun) | B45: 818 | C45: 371 | D45: 196 | E45: 496 | F45: 150 | G45: =SUM(B45:F45) -> 2031 | H45: 0.759
A46: Juin S2 (09-15 jun) | B46: 819 | C46: 356 | D46: 196 | E46: 518 | F46: 153 | G46: =SUM(B46:F46) -> 2042 | H46: 0.75
...

Sheet Qualité Eau
A1: SUIVI QUALITÉ DE L'EAU – JANVIER À DÉCEMBRE 2025 (48 semaines)
A3: NORMES RÉGLEMENTAIRES
A4: Paramètre | B4: Valeur réglementaire
A5: pH | B5: 7.2 – 7.6
A6: Chlore libre mg/L | B6: 0.4 – 1.4
A7: Température °C | B7: 26 – 28 (confort recommandé)
A8: Turbidité NTU | B8: < 0.5
A9: Trichloramines mg/L | B9: < 0.3
A11: RELEVÉS HEBDOMADAIRES – BASSIN PRINCIPAL
A12: Semaine | B12: pH | C12: Chlore libre | D12: Temp. (°C) | E12: Turbidité | F12: Trichloramines | G12: Contrôle | H12: Non-conf. | I12: Commentaire
A13: Janv. S1 | B13: 7.4 | C13: 1.1 | D13: 28.2 | E13: 0.25 | F13: 0.19 | G13: Conforme | H13: 0 | I13: –
A14: Janv. S2 | B14: 7.4 | C14: 1 | D14: 28.4 | E14: 0.28 | F14: 0.19 | G14: Conforme | H14: 0 | I14: –
A15: Janv. S3 | B15: 7.1 | C15: 1 | D15: 28.1 | E15: 0.21 | F15: 0.18 | G15: 1 écart | H15: 1 | I15: pH légèrement bas le 22/01, corrigé
A16: Janv. S4 | B16: 7.4 | C16: 1 | D16: 28.3 | E16: 0.31 | F16: 0.16 | G16: Conforme | H16: 0 | I16: –
A17: Fév. S1 | B17: 7.4 | C17: 1.4 | D17: 28.2 | E17: 0.25 | F17: 0.15 | G17: Conforme | H17: 0 | I17: –
A18: Fév. S2 | B18: 7.4 | C18: 1 | D18: 28 | E18: 0.48 | F18: 0.21 | G18: 1 écart | H18: 1 | I18: Turbidité 0.48 NTU le 12/02, backwash
A19: Fév. S3 | B19: 7.4 | C19: 1.3 | D19: 28.3 | E19: 0.33 | F19: 0.21 | G19: Conforme | H19: 0 | I19: –
A20: Fév. S4 | B20: 7.4 | C20: 1.2 | D20: 28.4 | E20: 0.24 | F20: 0.19 | G20: Conforme | H20: 0 | I20: –
A21: Mars S1 | B21: 7.5 | C21: 1.2 | D21: 28.2 | E21: 0.19 | F21: 0.14 | G21: Conforme | H21: 0 | I21: –
A22: Mars S2 | B22: 7.3 | C22: 1.3 | D22: 28.3 | E22: 0.27 | F22: 0.14 | G22: Conforme | H22: 0 | I22: –
A23: Mars S3 | B23: 7.5 | C23: 1.3 | D23: 28.1 | E23: 0.16 | F23: 0.17 | G23: Conforme | H23: 0 | I23: –
A24: Mars S4 | B24: 7.5 | C24: 1.1 | D24: 28.2 | E24: 0.16 | F24: 0.18 | G24: Conforme | H24: 0 | I24: –
... A60: Déc. S4 | B60: 7.5 | C60: 1.3 | D60: 25.4 | E60: 0.15 | F60: 0.12 | G60: Conforme | H60: 0 | I60: –
A61: MOYENNE / TOTAL | B61: =AVERAGE(B13:B60) -> 7.4020833 | C61: =AVERAGE(C13:C60) -> 1.1395833 | D61: =AVERAGE(D13:D60) -> 27.052083 | E61: =AVERAGE(E13:E60) -> 0.24375 | F61: =AVERAGE(F13:F60) -> 0.16625 | H61: =SUM(H13:H60) -> 5

Sheet Énergie
A1: SUIVI ÉNERGÉTIQUE & ENVIRONNEMENTAL – JANVIER À DÉCEMBRE 2025
A3: CONSOMMATIONS HEBDOMADAIRES
A4: Semaine | B4: Électricité (kWh) | C4: Gaz (m³) | D4: Eau (m³) | E4: Coût Élec. (€) | F4: Coût Gaz (€) | G4: Coût Eau (€) | H4: Coût Total (€) | I4: Prix élec. (€/kWh) | J4: Prix gaz (€/m³)
A5: Janv. S1 (06-12 jan) | B5: 8020 | C5: 1214 | D5: 420 | E5: 1363 | F5: 1093 | G5: 840 | H5: =SUM(E5:G5) -> 3296 | I5: =IF(B5<>0,E5/B5,0) -> 0.16995012 | J5: =IF(C5<>0,F5/C5,0) -> 0.90032949
A6: Janv. S2 (13-19 jan) | B6: 7950 | C6: 1217 | D6: 423 | E6: 1352 | F6: 1095 | G6: 846 | H6: =SUM(E6:G6) -> 3293 | I6: =IF(B6<>0,E6/B6,0) -> 0.17006289 | J6: =IF(C6<>0,F6/C6,0) -> 0.89975349
A7: Janv. S3 (20-26 jan) | B7: 8170 | C7: 1204 | D7: 420 | E7: 1389 | F7: 1084 | G7: 840 | H7: =SUM(E7:G7) -> 3313 | I7: =IF(B7<>0,E7/B7,0) -> 0.17001224 | J7: =IF(C7<>0,F7/C7,0) -> 0.90033223
A8: Janv. S4 (27-31 jan) | B8: 8120 | C8: 1228 | D8: 421 | E8: 1380 | F8: 1105 | G8: 842 | H8: =SUM(E8:G8) -> 3327 | I8: =IF(B8<>0,E8/B8,0) -> 0.16995074 | J8: =IF(C8<>0,F8/C8,0) -> 0.89983713
A9: Fév. S1 (03-09 fév) | B9: 8060 | C9: 1226 | D9: 435 | E9: 1378 | F9: 1116 | G9: 870 | H9: =SUM(E9:G9) -> 3364 | I9: =IF(B9<>0,E9/B9,0) -> 0.17096774 | J9: =IF(C9<>0,F9/C9,0) -> 0.91027732
A10: Fév. S2 (10-16 fév) | B10: 7940 | C10: 1220 | D10: 425 | E10: 1358 | F10: 1110 | G10: 850 | H10: =SUM(E10:G10) -> 3318 | I10: =IF(B10<>0,E10/B10,0) -> 0.17103275 | J10: =IF(C10<>0,F10/C10,0) -> 0.90983607
A11: Fév. S3 (17-23 fév) | B11: 8100 | C11: 1229 | D11: 425 | E11: 1385 | F11: 1118 | G11: 850 | H11: =SUM(E11:G11) -> 3353 | I11: =IF(B11<>0,E11/B11,0) -> 0.17098765 | J11: =IF(C11<>0,F11/C11,0) -> 0.90968267
A12: Fév. S4 (24-28 fév) | B12: 8150 | C12: 1228 | D12: 426 | E12: 1394 | F12: 1117 | G12: 852 | H12: =SUM(E12:G12) -> 3363 | I12: =IF(B12<>0,E12/B12,0) -> 0.17104294 | J12: =IF(C12<>0,F12/C12,0) -> 0.90960912
A13: Mars S1 (03-09 mar) | B13: 7810 | C13: 1089 | D13: 423 | E13: 1375 | F13: 1045 | G13: 846 | H13: =SUM(E13:G13) -> 3266 | I13: =IF(B13<>0,E13/B13,0) -> 0.17605634 | J13: =IF(C13<>0,F13/C13,0) -> 0.95959596
A14: Mars S2 (10-16 mar) | B14: 7720 | C14: 1110 | D14: 428 | E14: 1359 | F14: 1066 | G14: 856 | H14: =SUM(E14:G14) -> 3281 | I14: =IF(B14<>0,E14/B14,0) -> 0.17603627 | J14: =IF(C14<>0,F14/C14,0) -> 0.96036036
A15: Mars S3 (17-23 mar) | B15: 8010 | C15: 1077 | D15: 427 | E15: 1410 | F15: 1034 | G15: 854 | H15: =SUM(E15:G15) -> 3298 | I15: =IF(B15<>0,E15/B15,0) -> 0.17602996 | J15: =IF(C15<>0,F15/C15,0) -> 0.96007428
A16: Mars S4 (24-31 mar) | B16: 7900 | C16: 1114 | D16: 419 | E16: 1390 | F16: 1069 | G16: 838 | H16: =SUM(E16:G16) -> 3297 | I16: =IF(B16<>0,E16/B16,0) -> 0.17594937 | J16: =IF(C16<>0,F16/C16,0) -> 0.95960503
... A52: Déc. S4 (22-31 déc) | B52: 7850 | C52: 964 | D52: 322 | E52: 2080 | F52: 1677 | G52: 644 | H52: =SUM(E52:G52) -> 4401 | I52: =IF(B52<>0,E52/B52,0) -> 0.26496815 | J52: =IF(C52<>0,F52/C52,0) -> 1.7396266
A53: TOTAL 2025 | B53: =SUM(B5:B52) -> 368410 | C53: =SUM(C5:C52) -> 44203 | D53: =SUM(D5:D52) -> 18562 | E53: =SUM(E5:E52) -> 83355 | F53: =SUM(F5:F52) -> 59373 | G53: =SUM(G5:G52) -> 37124 | H53: =SUM(H5:H52) -> 179852 | I53: =IF(B53<>0,E53/B53,0) -> 0.22625607 | J53: =IF(C53<>0,F53/C53,0) -> 1.3431894
A55: OBJECTIFS ENVIRONNEMENTAUX 2025 – SUIVI MENSUEL
A56: Objectif | B56: Cible annuelle | C56: Janv. | D56: Fév. | E56: Mars | F56: Avr. | G56: Mai | H56: Juin | I56: Juil. | J56: Août | K56: Sept. | L56: Oct. | M56: Nov. | N56: Déc.
A57: Réduction élec. vs N-1 | B57: -5% | C57: -0.026 | D57: -0.021 | E57: -0.027 | F57: -0.024 | G57: -0.032 | H57: -0.027 | I57: -0.037 | J57: -0.048 | K57: -0.054 | L57: -0.042 | M57: -0.045 | N57: -0.044
A58: Réduction gaz vs N-1 | B58: -4% | C58: -0.042 | D58: -0.018 | E58: -0.035 | F58: -0.028 | G58: -0.021 | H58: -0.017 | I58: -0.151 | J58: -0.186 | K58: -0.199 | L58: -0.205 | M58: -0.228 | N58: -0.234
A59: Réduction eau vs N-1 | B59: -3% | C59: 0 | D59: 0.03 | E59: 0.019 | F59: 0.001 | G59: 0.016 | H59: 0.004 | I59: -0.054 | J59: -0.114 | K59: -0.112 | L59: -0.146 | M59: -0.151 | N59: -0.189
A60: Coût énergie/baigneur | B60: < 2.50 € | C60: =SUM(H5:H8)/Fréquentation!G9 -> 1.648679 | D60: =SUM(H9:H12)/Fréquentation!G17 -> 1.6263656 | E60: =SUM(H13:H16)/Fréquentation!G25 -> 1.6156872 | F60: =SUM(H17:H20)/Fréquentation!G33 -> 1.7249195 | G60: =SUM(H21:H24)/Fréquentation!G41 -> 1.9086788 | H60: =SUM(H25:H28)/Fréquentation!G49 -> 1.9481636 | I60: =SUM(H29:H32)/Fréquentation!G57 -> 2.1720964 | J60: =SUM(H33:H36)/Fréquentation!G65 -> 2.6171303 | K60: =SUM(H37:H40)/Fréquentation!G73 -> 2.4272888 | L60: =SUM(H41:H44)/Fréquentation!G81 -> 2.6642694 | M60: =SUM(H45:H48)/Fréquentation!G89 -> 2.9919847 | N60: =SUM(H49:H52)/Fréquentation!G97 -> 3.5637275
A61: Part énergies renouvelables | B61: 20% | C61: 0.08 | D61: 0.08 | E61: 0.1 | F61: 0.12 | G61: 0.15 | H61: 0.18 | I61: 0.19 | J61: 0.2 | K61: 0.17 | L61: 0.13 | M61: 0.1 | N61: 0.09

Sheet Finances
A1: SUIVI FINANCIER DÉTAILLÉ – JANVIER À DÉCEMBRE 2025
A3: RECETTES
A4: Poste | B4: Budget mensuel | C4: Janvier | D4: Février | E4: Mars | F4: Avril | G4: Mai | H4: Juin | I4: Juillet | J4: Août | K4: Septembre | L4: Octobre | M4: Novembre | N4: Décembre | O4: Total 2025
A5: Billetterie | B5: 41000 | C5: 31610 | D5: 32300 | E5: 31730 | F5: 31490 | G5: 29810 | H5: 31880 | I5: 27670 | J5: 22280 | K5: 24050 | L5: 23760 | M5: 22010 | N5: 19420 | O5: =SUM(C5:N5) -> 328010
A6: Abonnements | B6: 27500 | C6: 26852 | D6: 27048 | E6: 27391 | F6: 27587 | G6: 27734 | H6: 27930 | I6: 27489 | J6: 26460 | K6: 25088 | L6: 23961 | M6: 22589 | N6: 21413 | O6: =SUM(C6:N6) -> 311542
A7: Cours collectifs | B7: 10500 | C7: 10450 | D7: 10610 | E7: 10740 | F7: 10160 | G7: 10330 | H7: 9450 | I7: 4360 | J7: 2670 | K7: 6360 | L7: 6440 | M7: 5580 | N7: 4340 | O7: =SUM(C7:N7) -> 91490
A8: Location matériel | B8: 1800 | C8: 1770 | D8: 1810 | E8: 1790 | F8: 1780 | G8: 1700 | H8: 1790 | I8: 1510 | J8: 1200 | K8: 1370 | L8: 1350 | M8: 1260 | N8: 1100 | O8: =SUM(C8:N8) -> 18430
A9: Restauration | B9: 3000 | C9: 3050 | D9: 3130 | E9: 3090 | F9: 3070 | G9: 2930 | H9: 3090 | I9: 2600 | J9: 2080 | K9: 2370 | L9: 2320 | M9: 2180 | N9: 1900 | O9: =SUM(C9:N9) -> 31810
A10: Autres | B10: 1100 | C10: 1000 | D10: 1100 | E10: 1300 | F10: 1140 | G10: 1340 | H10: 1340 | I10: 1110 | J10: 1000 | K10: 1270 | L10: 1340 | M10: 970 | N10: 1020 | O10: =SUM(C10:N10) -> 13930
A11: TOTAL RECETTES | B11: =SUM(B5:B10) -> 84900 | C11: =SUM(C5:C10) -> 74732 | D11: =SUM(D5:D10) -> 75998 | E11: =SUM(E5:E10) -> 76041 | F11: =SUM(F5:F10) -> 75227 | G11: =SUM(G5:G10) -> 73844 | H11: =SUM(H5:H10) -> 75480 | I11: =SUM(I5:I10) -> 64739 | ... O11: =SUM(O5:O10) -> 795212
A13: CHARGES
A14: Poste | B14: Budget mensuel | C14: Janvier | D14: Février | E14: Mars | F14: Avril | G14: Mai | H14: Juin | I14: Juillet | J14: Août | K14: Septembre | L14: Octobre | M14: Novembre | N14: Décembre | O14: Total 2025
A15: Personnel (salaires) | B15: 37300 | C15: 36800 | D15: 36800 | E15: 36800 | F15: 36800 | G15: 36800 | H15: 36800 | I15: 39800 | J15: 39800 | K15: 36800 | L15: 36800 | M15: 36800 | N15: 36800 | O15: =SUM(C15:N15) -> 447600
A16: Charges patronales | B16: 18650 | C16: 18400 | D16: 18400 | E16: 18400 | F16: 18400 | G16: 18400 | H16: 18400 | I16: 19900 | J16: 19900 | K16: 18400 | L16: 18400 | M16: 18400 | N16: 18400 | O16: =SUM(C16:N16) -> 223800
A17: Électricité | B17: 6000 | C17: =SUM(Énergie!E5:E8) -> 5484 | D17: =SUM(Énergie!E9:E12) -> 5515 | E17: =SUM(Énergie!E13:E16) -> 5534 | F17: =SUM(Énergie!E17:E20) -> 6087 | G17: =SUM(Énergie!E21:E24) -> 6654 | H17: =SUM(Énergie!E25:E28) -> 7304 | I17: =SUM(Énergie!E29:E32) -> 7396 | J17: =SUM(Énergie!E33:E36) -> 7344 | K17: =SUM(Énergie!E37:E40) -> 7537 | L17: =SUM(Énergie!E41:E44) -> 7923 | M17: =SUM(Énergie!E45:E48) -> 8185 | N17: =SUM(Énergie!E49:E52) -> 8392 | O17: =SUM(C17:N17) -> 83355
A18: Gaz | B18: 4600 | C18: =SUM(Énergie!F5:F8) -> 4377 | D18: =SUM(Énergie!F9:F12) -> 4461 | E18: =SUM(Énergie!F13:F16) -> 4214 | F18: =SUM(Énergie!F17:F20) -> 4462 | G18: =SUM(Énergie!F21:F24) -> 4793 | H18: =SUM(Énergie!F25:F28) -> 5160 | I18: =SUM(Énergie!F29:F32) -> 4414 | J18: =SUM(Énergie!F33:F36) -> 4254 | K18: =SUM(Énergie!F37:F40) -> 4700 | L18: =SUM(Énergie!F41:F44) -> 5507 | M18: =SUM(Énergie!F45:F48) -> 6214 | N18: =SUM(Énergie!F49:F52) -> 6817 | O18: =SUM(C18:N18) -> 59373
A19: Eau | B19: 3600 | C19: =SUM(Énergie!G5:G8) -> 3368 | D19: =SUM(Énergie!G9:G12) -> 3422 | E19: =SUM(Énergie!G13:G16) -> 3394 | F19: =SUM(Énergie!G17:G20) -> 3378 | G19: =SUM(Énergie!G21:G24) -> 3288 | H19: =SUM(Énergie!G25:G28) -> 3396 | I19: =SUM(Énergie!G29:G32) -> 3058 | J19: =SUM(Énergie!G33:G36) -> 2702 | K19: =SUM(Énergie!G37:G40) -> 2902 | L19: =SUM(Énergie!G41:G44) -> 2870 | M19: =SUM(Énergie!G45:G48) -> 2772 | N19: =SUM(Énergie!G49:G52) -> 2574 | O19: =SUM(C19:N19) -> 37124
A20: Produits chimiques | B20: 3050 | C20: 3040 | D20: 3060 | E20: 3050 | F20: 3050 | G20: 3020 | H20: 3050 | I20: 2950 | J20: 2840 | K20: 2900 | L20: 2890 | M20: 2860 | N20: 2800 | O20: =SUM(C20:N20) -> 35510
A21: Maintenance préventive | B21: 2500 | C21: 2500 | D21: 2500 | E21: 2500 | F21: 2500 | G21: 2500 | H21: 2500 | I21: 2500 | J21: 2500 | K21: 2500 | L21: 2500 | M21: 2500 | N21: 2500 | O21: =SUM(C21:N21) -> 30000
A22: Maintenance corrective | B22: 1200 | C22: 850 | D22: 1420 | E22: 610 | F22: 980 | G22: 1250 | H22: 720 | I22: 1980 | J22: 540 | K22: 1130 | L22: 860 | M22: 1560 | N22: 940 | O22: =SUM(C22:N22) -> 12840
A23: Assurances | B23: 1500 | C23: 1500 | D23: 1500 | E23: 1500 | F23: 1500 | G23: 1500 | H23: 1500 | I23: 1500 | J23: 1500 | K23: 1500 | L23: 1500 | M23: 1500 | N23: 1500 | O23: =SUM(C23:N23) -> 18000
A24: Autres charges | B24: 1100 | C24: 1170 | D24: 1080 | E24: 1000 | F24: 1000 | G24: 1020 | H24: 1040 | I24: 1110 | J24: 1050 | K24: 1090 | L24: 1000 | M24: 1120 | N24: 1160 | O24: =SUM(C24:N24) -> 12840
A25: TOTAL CHARGES | B25: =SUM(B15:B24) -> 79500 | C25: =SUM(C15:C24) -> 77489 | D25: =SUM(D15:D24) -> 78158 | E25: =SUM(E15:E24) -> 77002 | F25: =SUM(F15:F24) -> 78157 | G25: =SUM(G15:G24) -> 79225 | H25: =SUM(H15:H24) -> 79870 | I25: =SUM(I15:I24) -> 84608 | ... O25: =SUM(O15:O24) -> 960442
A27: RÉSULTAT D'EXPLOITATION | B27: =B11-B25 -> 5400 | C27: =C11-C25 -> -2757 | D27: =D11-D25 -> -2160 | E27: =E11-E25 -> -961 | F27: =F11-F25 -> -2930 | G27: =G11-G25 -> -5381 | H27: =H11-H25 -> -4390 | I27: =I11-I25 -> -19869 | ... O27: =O11-O25 -> -165230
A29: ÉVOLUTION & RATIOS
A30: Poste | B30: Budget mensuel | C30: Janvier | D30: Février | E30: Mars | F30: Avril | G30: Mai | H30: Juin | I30: Juillet | J30: Août | K30: Septembre | L30: Octobre | M30: Novembre | N30: Décembre | O30: Total 2025
A31: Recettes totales / Baigneur (€) | B31: – | C31: =IF(Fréquentation!G9<>0,C11/Fréquentation!G9,0) -> 9.3135593 | D31: =IF(Fréquentation!G17<>0,D11/Fréquentation!G17,0) -> 9.2252974 | E31: =IF(Fréquentation!G25<>0,E11/Fréquentation!G25,0) -> 9.348537 | F31: =IF(Fréquentation!G33<>0,F11/Fréquentation!G33,0) -> 9.317191 | G31: =IF(Fréquentation!G41<>0,G11/Fréquentation!G41,0) -> 9.565285 | H31: =IF(Fréquentation!G49<>0,H11/Fréquentation!G49,0) -> 9.2715883 | I31: =IF(Fréquentation!G57<>0,I11/Fréquentation!G57,0) -> 9.4578524 | J31: =IF(Fréquentation!G65<>0,J11/Fréquentation!G65,0) -> 10.192167 | K31: =IF(Fréquentation!G73<>0,K11/Fréquentation!G73,0) -> 9.701459 | L31: =IF(Fréquentation!G81<>0,L11/Fréquentation!G81,0) -> 9.6716247 | M31: =IF(Fréquentation!G89<>0,M11/Fréquentation!G89,0) -> 9.5119359 | N31: =IF(Fréquentation!G97<>0,N11/Fréquentation!G97,0) -> 9.8583166 | O31: =IF(SUM(Fréquentation!G9,Fréquentation!G17,Fréquentation!G25,Fréquentation!G33,Fréquentation!G41,Fréquentation!G49,Fréquentation!G57,Fréquentation!G65,Fréquentation!G73,Fréquentation!G81,Fréquentation!G89,Fréquentation!G97)<>0,O11/SUM(Fréquentation!G9,Fréquentation!G17,Fréquentation!G25,Fréquentation!G33,Fréquentation!G41,Fréquentation!G49,Fréquentation!G57,Fréquentation!G65,Fréquentation!G73,Fréquentation!G81,Fréquentation!G89,Fréquentation!G97),0) -> 9.4980173
A32: Charges totales / Baigneur (€) | B32: – | C32: =IF(Fréquentation!G9<>0,C25/Fréquentation!G9,0) -> 9.6571535 | D32: =IF(Fréquentation!G17<>0,D25/Fréquentation!G17,0) -> 9.487497 | E32: =IF(Fréquentation!G25<>0,E25/Fréquentation!G25,0) -> 9.4666831 | F32: =IF(Fréquentation!G33<>0,F25/Fréquentation!G33,0) -> 9.6800842 | G32: =IF(Fréquentation!G41<>0,G25/Fréquentation!G41,0) -> 10.262306 | H32: =IF(Fréquentation!G49<>0,H25/Fréquentation!G49,0) -> 9.810834 | I32: =IF(Fréquentation!G57<>0,I25/Fréquentation!G57,0) -> 12.360555 | J32: =IF(Fréquentation!G65<>0,J25/Fréquentation!G65,0) -> 15.086018 | K32: =IF(Fréquentation!G73<>0,K25/Fréquentation!G73,0) -> 12.739939 | L32: =IF(Fréquentation!G81<>0,L25/Fréquentation!G81,0) -> 13.117032 | M32: =IF(Fréquentation!G89<>0,M25/Fréquentation!G89,0) -> 14.272696 | N32: =IF(Fréquentation!G97<>0,N25/Fréquentation!G97,0) -> 16.409419 | O32: =IF(SUM(Fréquentation!G9,Fréquentation!G17,Fréquentation!G25,Fréquentation!G33,Fréquentation!G41,Fréquentation!G49,Fréquentation!G57,Fréquentation!G65,Fréquentation!G73,Fréquentation!G81,Fréquentation!G89,Fréquentation!G97)<>0,O25/SUM(Fréquentation!G9,Fréquentation!G17,Fréquentation!G25,Fréquentation!G33,Fréquentation!G41,Fréquentation!G49,Fréquentation!G57,Fréquentation!G65,Fréquentation!G73,Fréquentation!G81,Fréquentation!G89,Fréquentation!G97),0) -> 11.471525
A33: Marge billetterie après énergie (%) | B33: – | C33: =IF(C5<>0,(C5-C17-C18-C19)/C5,0) -> 0.5814932 | D33: =IF(D5<>0,(D5-D17-D18-D19)/D5,0) -> 0.58520124 | E33: =IF(E5<>0,(E5-E17-E18-E19)/E5,0) -> 0.58581784 | F33: =IF(F5<>0,(F5-F17-F18-F19)/F5,0) -> 0.55773261 | G33: =IF(G5<>0,(G5-G17-G18-G19)/G5,0) -> 0.50570278 | H33: =IF(H5<>0,(H5-H17-H18-H19)/H5,0) -> 0.50250941 | I33: =IF(I5<>0,(I5-I17-I18-I19)/I5,0) -> 0.46266715 | J33: =IF(J5<>0,(J5-J17-J18-J19)/J5,0) -> 0.35816876 | ... O33: =IF(O5<>0,(O5-O17-O18-O19)/O5,0) -> 0.45168745

Sheet RH & Sécurité
A1: RESSOURCES HUMAINES & SÉCURITÉ – JANVIER À DÉCEMBRE 2025
A3: EFFECTIFS PAR POSTE
A4: Poste | B4: ETP Prévu | C4: Janv. | D4: Fév. | E4: Mars | F4: Avr. | G4: Mai | H4: Juin | I4: Juil. | J4: Août | K4: Sept. | L4: Oct. | M4: Nov. | N4: Déc.
A5: Maîtres-nageurs | B5: 8 | C5: 7.5 | D5: 7.8 | E5: 8 | F5: 8 | G5: 8 | H5: 7.8 | I5: 9.5 | J5: 9.5 | K5: 8 | L5: 7.8 | M5: 8 | N5: 7.6
A6: Accueil / Caisse | B6: 3 | C6: 3 | D6: 3 | E6: 3 | F6: 3 | G6: 3 | H6: 3 | I6: 3.5 | J6: 3.5 | K6: 3 | L6: 3 | M6: 3 | N6: 3
A7: Technique / Piscine | B7: 2 | C7: 2 | D7: 2 | E7: 2 | F7: 2 | G7: 2 | H7: 2 | I7: 2 | J7: 2 | K7: 2 | L7: 2 | M7: 2 | N7: 2
A8: Nettoyage | B8: 3 | C8: 2.8 | D8: 2.9 | E8: 3 | F8: 3 | G8: 3 | H8: 3 | I8: 3.2 | J8: 3.2 | K8: 3 | L8: 2.9 | M8: 3 | N8: 2.8
A9: Direction / Admin. | B9: 2 | C9: 2 | D9: 2 | E9: 2 | F9: 2 | G9: 2 | H9: 2 | I9: 2 | J9: 2 | K9: 2 | L9: 2 | M9: 2 | N9: 2
A10: TOTAL ETP | B10: =SUM(B5:B9) -> 18 | C10: =SUM(C5:C9) -> 17.3 | D10: =SUM(D5:D9) -> 17.7 | E10: =SUM(E5:E9) -> 18 | F10: =SUM(F5:F9) -> 18 | G10: =SUM(G5:G9) -> 18 | H10: =SUM(H5:H9) -> 17.8 | I10: =SUM(I5:I9) -> 20.2 | ... N10: =SUM(N5:N9) -> 17.4
A12: SUIVI ABSENTÉISME MENSUEL
A13: Indicateur | B13: Budget/Cible | C13: Janvier | D13: Février | E13: Mars | F13: Avril | G13: Mai | H13: Juin | I13: Juillet | J13: Août | K13: Septembre | L13: Octobre | M13: Novembre | N13: Décembre
A14: Jours d'absence | B14: < 10 j/mois | C14: 8 | D14: 12 | E14: 6 | F14: 9 | G14: 5 | H14: 7 | I14: 6 | J14: 4 | K14: 9 | L14: 8 | M14: 11 | N14: 10
A15: Taux d'absentéisme | B15: < 3.0% | C15: 0.022 | D15: 0.033 | E15: 0.017 | F15: 0.025 | G15: 0.014 | H15: 0.019 | I15: 0.015 | J15: 0.01 | K15: 0.025 | L15: 0.022 | M15: 0.03 | N15: 0.028
A16: Heures supp. réalisées | B16: – | C16: 42 | D16: 38 | E16: 35 | F16: 44 | G16: 52 | H16: 58 | I16: 74 | J16: 69 | K16: 40 | L16: 36 | M16: 39 | N16: 41
A17: Formations réalisées | B17: ≥ 2/mois | C17: 2 | D17: 3 | E17: 1 | F17: 2 | G17: 2 | H17: 1 | I17: 0 | J17: 0 | K17: 3 | L17: 2 | M17: 2 | N17: 1
A18: Accidents / incidents | B18: 0 | C18: 2 | D18: 2 | E18: 1 | F18: 0 | G18: 1 | H18: 1 | I18: 1 | J18: 0 | K18: 2 | L18: 1 | M18: 1 | N18: 1
A20: FORMATIONS & HABILITATIONS – SUIVI 2025
A21: Formation / Habilitation | B21: Nb concernés | C21: Validité | D21: T1 (janv.-mars) | E21: T2 (avr.-juin) | F21: T3 (juil.-sept.) | G21: T4 (oct.-déc.) | H21: Statut
A22: BNSSA (Brevet MNS) | B22: 8 | C22: 5 ans | D22: À jour | E22: À jour | F22: À jour | G22: À jour | H22: OK – Éch. 2027
A23: PSE1 (Premiers Secours) | B23: 8 | C23: 2 ans | D23: À jour | E23: À jour | F23: À jour | G23: Réalisé | H23: OK – Renouvelé nov. 2025
A24: Recyclage PSE1 | B24: 8 | C24: Annuel | D24: Réalisé | E24: – | F24: – | G24: – | H24: OK
A25: Formation POSS | B25: 5 | C25: Annuel | D25: Réalisé | E25: – | F25: – | G25: – | H25: OK
A26: Habilitation élec. B1V | B26: 2 | C26: 3 ans | D26: – | E26: – | F26: – | G26: – | H26: OK – Éch. juin 2026
A27: Gestes & postures | B27: 18 | C27: Annuel | D27: Réalisé | E27: – | F27: – | G27: – | H27: OK
A28: HACCP restauration | B28: 2 | C28: 2 ans | D28: – | E28: À planifier | F28: Réalisé | G28: – | H28: OK – Renouvelé sept. 2025
A29: Exercice évacuation incendie | B29: 18 | C29: Annuel | D29: Réalisé | E29: – | F29: – | G29: Réalisé | H29: OK
A30: Sensibilisation DUERP | B30: 18 | C30: Annuel | D30: – | E30: Réalisé | F30: – | G30: – | H30: OK
A32: REGISTRE INCIDENTS & ACCIDENTS – 2025
A33: Date | B33: Type d'incident | C33: Personnes impliquées | D33: Localisation | E33: Gravité | F33: Actions correctives | G33: Clôturé ? | H33: Référence
A34: 15/01/2025 | B34: Chute bord bassin | C34: 1 baigneur adulte | D34: Plage bassin nage | E34: Légère (contusion) | F34: Revêtement antidérapant | G34: Oui | H34: INC-2025-001
A35: 22/01/2025 | B35: Malaise baigneur | C35: 1 baigneur senior | D35: Bassin nage | E35: Moyenne (MNS intervenu) | F35: POSS + formation PSE | G35: Oui | H35: INC-2025-002
A36: 08/02/2025 | B36: Chute vestiaires | C36: 1 employé ménage | D36: Vestiaires femmes | E36: Légère (lombaire) | F36: Déclaration AT, adaptation poste | G36: Oui | H36: INC-2025-003
A37: 14/02/2025 | B37: Non-conformité eau | C37: – | D37: Bassin polyvalent | E37: Mineure (qualité) | F37: Backwash + ajustement chlore | G37: Oui | H37: INC-2025-004
A38: 04/03/2025 | B38: Blessure toboggan | C38: 1 enfant 8 ans | D38: Toboggan | E38: Légère (écorchure) | F38: Inspection + signalétique | G38: Oui | H38: INC-2025-005
A39: 17/05/2025 | B39: Glissade douches | C39: 1 baigneur adulte | D39: Douches | E39: Légère (contusion) | F39: Nettoyage renforcé | G39: Oui | H39: INC-2025-006
A40: 18/06/2025 | B40: Incivisme vestiaires | C40: 1 adulte | D40: Vestiaires hommes | E40: Comportement | F40: Exclusion temp. + rappel règles | G40: Oui | H40: INC-2025-007
A41: 23/07/2025 | B41: Coupure pied | C41: 1 enfant 10 ans | D41: Plage extérieure | E41: Légère (plaie) | F41: Inspection des dalles | G41: Oui | H41: INC-2025-008
A42: 09/09/2025 | B42: Altercation à l'accueil | C42: 1 usager abonné | D42: Accueil | E42: Comportement (verbal) | F42: Rappel règlement, médiation direction | G42: Oui | H42: INC-2025-009
A43: 26/09/2025 | B43: Malaise baigneur | C43: 1 participante aquagym | D43: Bassin polyvalent | E43: Moyenne (frissons, MNS intervenu) | F43: Prise en charge, appel famille | G43: Oui | H43: INC-2025-010
A44: 15/10/2025 | B44: Chute escalier toboggan | C44: 1 adolescent | D44: Toboggan | E44: Légère (entorse) | F44: Signalétique renforcée | G44: Oui | H44: INC-2025-011
...
